Workbook

Sheet Questionário
C1: Nada a ver comigo | D1: Um pouco a ver comigo | E1: Mais ou menos a ver comigo | F1: Muito a ver comigo | G1: Tudo a ver comigo
A2: 1 | B2: Sei o que fazer para que as pessoas se sintam bem | C2: 0 | D2: 1 | E2: 2 | F2: 3 | G2: 4
A3: 2 | B3: Trato todas as pessoas com igualdade | C3: 0 | D3: 1 | E3: 2 | F3: 3 | G3: 4
A4: 3 | B4: Faço as coisas de jeitos diferentes | C4: 0 | D4: 1 | E4: 2 | F4: 3 | G4: 4
A5: 4 | B5: Sou competente em dar conselhos | C5: 0 | D5: 1 | E5: 2 | F5: 3 | G5: 4
A6: 5 | B6: Ter que aprender coisas novas me motiva | C6: 0 | D6: 1 | E6: 2 | F6: 3 | G6: 4
A7: 6 | B7: Faço bons julgamentos, mesmo em situações dificeis | C7: 0 | D7: 1 | E7: 2 | F7: 3 | G7: 4
A8: 7 | B8: Penso em diferentes possibilidades quando tomo uma decisão | C8: 0 | D8: 1 | E8: 2 | F8: 3 | G8: 4
A9: 8 | B9: Sinto que a minha vida tem um sentido maior | C9: 0 | D9: 1 | E9: 2 | F9: 3 | G9: 4
A10: 9 | B10: Sou competente para analisar problemas por diferentes "Angulos" | C10: 0 | D10: 1 | E10: 2 | F10: 3 | G10: 4
A11: 10 | B11: Não minto para agradar pessoas | C11: 0 | D11: 1 | E11: 2 | F11: 3 | G11: 4
A12: 11 | B12: Reconheço meus defeitos | C12: 0 | D12: 1 | E12: 2 | F12: 3 | G12: 4
A13: 12 | B13: Sou paciente | C13: 0 | D13: 1 | E13: 2 | F13: 3 | G13: 4
... A28: 27 | B28: Creio que amanhã será melhor que hoje | C28: 0 | D28: 1 | E28: 2 | F28: 3 | G28: 4
C33: Nada a ver comigo | D33: Um pouco a ver comigo | E33: Mais ou menos a ver comigo | F33: Muito a ver comigo | G33: Tudo a ver comigo
A34: 28 | B34: Acredito em uma força sagrada que nos liga um ao outro | C34: 0 | D34: 1 | E34: 2 | F34: 3 | G34: 4
A35: 29 | B35: Penso muito antes de tomar uma decisão | C35: 0 | D35: 1 | E35: 2 | F35: 3 | G35: 4
A36: 30 | B36: Crio coisas úteis | C36: 0 | D36: 1 | E36: 2 | F36: 3 | G36: 4
A37: 31 | B37: Penso que todo mundo deve dedicar parte de seu tempo para melhorar o local de habita | C37: 0 | D37: 1 | E37: 2 | F37: 3 | G37: 4
A38: 32 | B38: Perdoo as pessoas facilmente | C38: 0 | D38: 1 | E38: 2 | F38: 3 | G38: 4
A39: 33 | B39: Sou uma pessoa verdadeira | C39: 0 | D39: 1 | E39: 2 | F39: 3 | G39: 4
A40: 34 | B40: Consigo criar um bom ambiente nos grupos que trabalho | C40: 0 | D40: 1 | E40: 2 | F40: 3 | G40: 4
A41: 35 | B41: Enfrento perigos para fazer o bem | C41: 0 | D41: 1 | E41: 2 | F41: 3 | G41: 4
A42: 36 | B42: Analiso o que as pessoas dizem antes de dar minha opinião | C42: 0 | D42: 1 | E42: 2 | F42: 3 | G42: 4
A43: 37 | B43: Sou uma pessoa amorosa | C43: 0 | D43: 1 | E43: 2 | F43: 3 | G43: 4
A44: 38 | B44: Mantenho a calma em situações dificeis | C44: 0 | D44: 1 | E44: 2 | F44: 3 | G44: 4
A45: 39 | B45: Sei admirar a beleza que existe no mundo | C45: 0 | D45: 1 | E45: 2 | F45: 3 | G45: 4
... A63: 57 | B63: Corro risco para fazer o que tem que ser feito | C63: 0 | D63: 1 | E63: 2 | F63: 3 | G63: 4
C64: Nada a ver comigo | D64: Um pouco a ver comigo | E64: Mais ou menos a ver comigo | F64: Muito a ver comigo | G64: Tudo a ver comigo
A65: 58 | B65: As regras devem ser cumpridas por todos | C65: 0 | D65: 1 | E65: 2 | F65: 3 | G65: 4
A66: 59 | B66: Tenho muita facilidade para perceber os sentimentos das pessoas mesmo sem elas me dizerem | C66: 0 | D66: 1 | E66: 2 | F66: 3 | G66: 4
A67: 60 | B67: Sou uma pessoa cuidadosa | C67: 0 | D67: 1 | E67: 2 | F67: 3 | G67: 4
A68: 61 | B68: Faço coisas concretas para tornar o mundo um lugar melhor para se viver | C68: 0 | D68: 1 | E68: 2 | F68: 3 | G68: 4
A69: 62 | B69: Tenho facilidade para organizar trabalhos em grupo | C69: 0 | D69: 1 | E69: 2 | F69: 3 | G69: 4
A70: 63 | B70: Consigo ajudar pessoas a se entenderem quando há uma discussão | C70: 0 | D70: 1 | E70: 2 | F70: 3 | G70: 4
A71: 64 | B71: Tenho facilidade para fazer uma situação chata se tornar divertida | C71: 0 | D71: 1 | E71: 2 | F71: 3 | G71: 4
A72: 65 | B72: Costumo tomar decisões quando estou ciente das consequencais dos meus atos | C72: 0 | D72: 1 | E72: 2 | F72: 3 | G72: 4
A73: 66 | B73: Dar é mais importante que receber | C73: 0 | D73: 1 | E73: 2 | F73: 3 | G73: 4
A74: 67 | B74: Eu me sinto bem ao fazer a coisa certa mesmo que isso possa me prejudicar | C74: 0 | D74: 1 | E74: 2 | F74: 3 | G74: 4
A75: 68 | B75: Sou uma pessoa justa | C75: 0 | D75: 1 | E75: 2 | F75: 3 | G75: 4
...

Sheet Resposta
A1: 1
A2: 2
A3: 3
A4: 4
A5: 5
A6: 6
A7: 7
A8: 8
A9: 9
A10: 10
A11: 11
A12: 12
... A71: 71

Sheet Avaliação
A1: 1. Sabedoria e Conhecimento (criatividade, curiosidade, amor pelo aprendizado, mentalidade crítica, perspectiva) | B1: 1 | C1: Criatividade | D1: =Resposta!B3+Resposta!B30+Resposta!B48 -> 0 | E1: =Resposta!C3+Resposta!C30+Resposta!C48 -> 0
B2: 2 | C2: Curiosidade | D2: =Resposta!B23+Resposta!B25+Resposta!B69 -> 0 | E2: =Resposta!C23+Resposta!C25+Resposta!C69 -> 0
B3: 3 | C3: Pensamento Crítico | D3: =Resposta!B7+Resposta!B9+Resposta!B71 -> 0 | E3: =Resposta!C7+Resposta!C9+Resposta!C71 -> 0
B4: 4 | C4: Amor ao Aprendizado | D4: =Resposta!B5+Resposta!B17+Resposta!B45 -> 0 | E4: =Resposta!C5+Resposta!C17+Resposta!C45 -> 0
B5: 5 | C5: Sensatez | D5: =Resposta!B4+Resposta!B63+Resposta!B6 -> 0 | E5: =Resposta!C4+Resposta!C63+Resposta!C6 -> 0
A6: 2. Coragem (bravura, persistência, integridade, entusiasmo) | B6: 6 | C6: Bravura | D6: =Resposta!B35+Resposta!B57+Resposta!B67 -> 0 | E6: =Resposta!C35+Resposta!C57+Resposta!C67 -> 0
B7: 7 | C7: Perseverança | D7: =Resposta!B40+Resposta!B47+Resposta!B52 -> 0 | E7: =Resposta!C40+Resposta!C47+Resposta!C52 -> 0
B8: 8 | C8: Autenticidade | D8: =Resposta!B10+Resposta!B33+Resposta!B41 -> 0 | E8: =Resposta!C10+Resposta!C33+Resposta!C41 -> 0
B9: 9 | C9: Vitalidade | D9: =Resposta!B13+Resposta!B18+Resposta!B53 -> 0 | E9: =Resposta!C13+Resposta!C18+Resposta!C53 -> 0
A10: 3. Humanidade (amor, bondade, inteligência emocional) | B10: 10 | C10: Amor | D10: =Resposta!B16+Resposta!B37+Resposta!B70 -> 0 | E10: =Resposta!C16+Resposta!C37+Resposta!C70 -> 0
B11: 11 | C11: Bondade | D11: =Resposta!B21+Resposta!B50+Resposta!B66 -> 0 | E11: =Resposta!C21+Resposta!C50+Resposta!C66 -> 0
B12: 12 | C12: Inteligência Social | D12: =Resposta!B1+Resposta!B20+Resposta!B59 -> 0 | E12: =Resposta!C1+Resposta!C20+Resposta!C59 -> 0
A13: 4. Justiça (cidadania, equidade, liderança) | B13: 13 | C13: Cidadania | D13: =Resposta!B31+Resposta!B34+Resposta!B61 -> 0 | E13: =Resposta!C31+Resposta!C34+Resposta!C61 -> 0
B14: 14 | C14: Imparcialidade | D14: =Resposta!B2+Resposta!B58+Resposta!B68 -> 0 | E14: =Resposta!C2+Resposta!C58+Resposta!C68 -> 0
B15: 15 | C15: Liderança | D15: =Resposta!B19+Resposta!B62+Resposta!B55 -> 0 | E15: =Resposta!C19+Resposta!C62+Resposta!C55 -> 0
A16: 5. Moderação (perdão, humildade, prudência, autorregulação) | B16: 16 | C16: Perdão | D16: =Resposta!B26+Resposta!B32+Resposta!B54 -> 0 | E16: =Resposta!C26+Resposta!C32+Resposta!C54 -> 0
B17: 17 | C17: Modéstia | D17: =Resposta!B11+Resposta!B46+Resposta!B56 -> 0 | E17: =Resposta!C11+Resposta!C46+Resposta!C56 -> 0
B18: 18 | C18: Prudência | D18: =Resposta!B29+Resposta!B36+Resposta!B65 -> 0 | E18: =Resposta!C29+Resposta!C36+Resposta!C65 -> 0
B19: 19 | C19: Autorregulação | D19: =Resposta!B12+Resposta!B38+Resposta!B60 -> 0 | E19: =Resposta!C12+Resposta!C38+Resposta!C60 -> 0
A20: 6. Transcendência (apreciação da beleza, gratidão, esperança, humor, espiritualidade) | B20: 20 | C20: Apreciação ao Belo | D20: =Resposta!B39+Resposta!B43 -> 0 | E20: =Resposta!C39+Resposta!C43 -> 0
B21: 21 | C21: Gratidão | D21: =Resposta!B22+Resposta!B24+Resposta!B44 -> 0 | E21: =Resposta!C22+Resposta!C24+Resposta!C44 -> 0
B22: 22 | C22: Humor | D22: =Resposta!B14+Resposta!B42+Resposta!B64 -> 0 | E22: =Resposta!C14+Resposta!C42+Resposta!C64 -> 0
B23: 23 | C23: Esperança | D23: =Resposta!B15+Resposta!B27+Resposta!B49 -> 0 | E23: =Resposta!C15+Resposta!C27+Resposta!C49 -> 0
B24: 24 | C24: Espiritualidade | D24: =Resposta!B8+Resposta!B28+Resposta!B51 -> 0 | E24: =Resposta!C8+Resposta!C28+Resposta!C51 -> 0
